Workbook

Sheet DIM _CUSTOMERS
A1: Email | B1: Name - First | C1: Name - Last | D1: BirthDate | E1: Gender | F1: Continent | G1: Country | H1: Status | I1: Age | J1: AgeGroup
A2: ablumsom48@samsung.com | B2: Alister | C2: Blumsom | D2: 33404 | E2: M | F2: =_xlfn.XLOOKUP(DIM_CUSTOMERS[[#This Row],[Country]],DIM_COUNTRIES!A:A,DIM_COUNTRIES!B:B) -> North America | G2: United States | H2: Married | I2: =DATEDIF(DIM_CUSTOMERS[[#This Row],[BirthDate]],TODAY(),"Y") -> 33 | J2: =IF(I2<23, "Child", IF(I2<65, "Adult", "Senior")) -> Adult
A3: abolesma40@chron.com | B3: Aldo | C3: Bolesma | D3: 30254 | E3: M | F3: =_xlfn.XLOOKUP(DIM_CUSTOMERS[[#This Row],[Country]],DIM_COUNTRIES!A:A,DIM_COUNTRIES!B:B) -> North America | G3: United States | H3: Married | I3: =DATEDIF(DIM_CUSTOMERS[[#This Row],[BirthDate]],TODAY(),"Y") -> 42 | J3: =IF(I3<23, "Child", IF(I3<65, "Adult", "Senior")) -> Adult
A4: abonnefin35@bloglines.com | B4: Allis | C4: Bonnefin | D4: 20779 | E4: F | F4: =_xlfn.XLOOKUP(DIM_CUSTOMERS[[#This Row],[Country]],DIM_COUNTRIES!A:A,DIM_COUNTRIES!B:B) -> North America | G4: United States | H4: Married | I4: =DATEDIF(DIM_CUSTOMERS[[#This Row],[BirthDate]],TODAY(),"Y") -> 68 | J4: =IF(I4<23, "Child", IF(I4<65, "Adult", "Senior")) -> Senior
A5: aborwick7t@xrea.com | B5: Anica | C5: Borwick | D5: 16579 | E5: F | F5: =_xlfn.XLOOKUP(DIM_CUSTOMERS[[#This Row],[Country]],DIM_COUNTRIES!A:A,DIM_COUNTRIES!B:B) -> Asia | G5: China | H5: Married | I5: =DATEDIF(DIM_CUSTOMERS[[#This Row],[BirthDate]],TODAY(),"Y") -> 80 | J5: =IF(I5<23, "Child", IF(I5<65, "Adult", "Senior")) -> Senior
A6: abozward4y@google.co.jp | B6: Andros | C6: Bozward | D6: 25020 | E6: M | F6: =_xlfn.XLOOKUP(DIM_CUSTOMERS[[#This Row],[Country]],DIM_COUNTRIES!A:A,DIM_COUNTRIES!B:B) -> Europe | G6: Bulgaria | H6: Married | I6: =DATEDIF(DIM_CUSTOMERS[[#This Row],[BirthDate]],TODAY(),"Y") -> 56 | J6: =IF(I6<23, "Child", IF(I6<65, "Adult", "Senior")) -> Adult
A7: acopoby@dell.com | B7: Aymer | C7: Copo | D7: 23053 | E7: M | F7: =_xlfn.XLOOKUP(DIM_CUSTOMERS[[#This Row],[Country]],DIM_COUNTRIES!A:A,DIM_COUNTRIES!B:B) -> North America | G7: United States | H7: Married | I7: =DATEDIF(DIM_CUSTOMERS[[#This Row],[BirthDate]],TODAY(),"Y") -> 62 | J7: =IF(I7<23, "Child", IF(I7<65, "Adult", "Senior")) -> Adult
A8: acromerdf@homestead.com | B8: Arabelle | C8: Cromer | D8: 21732 | E8: M | F8: =_xlfn.XLOOKUP(DIM_CUSTOMERS[[#This Row],[Country]],DIM_COUNTRIES!A:A,DIM_COUNTRIES!B:B) -> North America | G8: United States | H8: Married | I8: =DATEDIF(DIM_CUSTOMERS[[#This Row],[BirthDate]],TODAY(),"Y") -> 65 | J8: =IF(I8<23, "Child", IF(I8<65, "Adult", "Senior")) -> Senior
A9: adarnell1l@tuttocitta.it | B9: Audry | C9: Darnell | D9: 37680 | E9: F | F9: =_xlfn.XLOOKUP(DIM_CUSTOMERS[[#This Row],[Country]],DIM_COUNTRIES!A:A,DIM_COUNTRIES!B:B) -> North America | G9: United States | H9: Married | I9: =DATEDIF(DIM_CUSTOMERS[[#This Row],[BirthDate]],TODAY(),"Y") -> 22 | J9: =IF(I9<23, "Child", IF(I9<65, "Adult", "Senior")) -> Child
A10: adaynterdn@theguardian.com | B10: Addi | C10: Daynter | D10: 32727 | E10: M | F10: =_xlfn.XLOOKUP(DIM_CUSTOMERS[[#This Row],[Country]],DIM_COUNTRIES!A:A,DIM_COUNTRIES!B:B) -> North America | G10: United States | H10: Married | I10: =DATEDIF(DIM_CUSTOMERS[[#This Row],[BirthDate]],TODAY(),"Y") -> 35 | J10: =IF(I10<23, "Child", IF(I10<65, "Adult", "Senior")) -> Adult
A11: adetoc2l@github.com | B11: Allard | C11: Detoc | D11: 36757 | E11: M | F11: =_xlfn.XLOOKUP(DIM_CUSTOMERS[[#This Row],[Country]],DIM_COUNTRIES!A:A,DIM_COUNTRIES!B:B) -> Australia | G11: Australia | H11: Married | I11: =DATEDIF(DIM_CUSTOMERS[[#This Row],[BirthDate]],TODAY(),"Y") -> 24 | J11: =IF(I11<23, "Child", IF(I11<65, "Adult", "Senior")) -> Adult
A12: adomercc8@nature.com | B12: Abbot | C12: Domerc | D12: 39127 | E12: F | F12: =_xlfn.XLOOKUP(DIM_CUSTOMERS[[#This Row],[Country]],DIM_COUNTRIES!A:A,DIM_COUNTRIES!B:B) -> North America | G12: United States | H12: Married | I12: =DATEDIF(DIM_CUSTOMERS[[#This Row],[BirthDate]],TODAY(),"Y") -> 18 | J12: =IF(I12<23, "Child", IF(I12<65, "Adult", "Senior")) -> Child
A13: adukedq@geocities.jp | B13: Amby | C13: Duke | D13: 27853 | E13: F | F13: =_xlfn.XLOOKUP(DIM_CUSTOMERS[[#This Row],[Country]],DIM_COUNTRIES!A:A,DIM_COUNTRIES!B:B) -> North America | G13: United States | H13: Married | I13: =DATEDIF(DIM_CUSTOMERS[[#This Row],[BirthDate]],TODAY(),"Y") -> 49 | J13: =IF(I13<23, "Child", IF(I13<65, "Adult", "Senior")) -> Adult
... A584: zperren7k@vinaora.com | B584: Zelma | C584: Perren | D584: 18803 | E584: F | F584: =_xlfn.XLOOKUP(DIM_CUSTOMERS[[#This Row],[Country]],DIM_COUNTRIES!A:A,DIM_COUNTRIES!B:B) -> Asia | G584: China | H584: Married | I584: =DATEDIF(DIM_CUSTOMERS[[#This Row],[BirthDate]],TODAY(),"Y") -> 73 | J584: =IF(I584<23, "Child", IF(I584<65, "Adult", "Senior")) -> Senior

Sheet DIM_FLOWERSHOPS
A1: ShopID | B1: Shop Name | C1: Continent | D1: Country | E1: Employees | F1: Founded | G1: Seniority | H1: Store Size Class
A2: A10UP7 | B2: Bloom Oasis | C2: Australia | D2: Australia | E2: 3 | F2: 42371 | G2: =IF(YEAR(TODAY())-YEAR(DIM_FLOWERSHOPS[[#This Row],[Founded]])<=2, "A", IF(YEAR(TODAY())-YEAR(DIM_FLOWERSHOPS[[#This Row],[Founded]])<=8, "B", "C")) -> C | H2: =IF(E2<=5, "Small", IF(E2<=10, "Medium", "Large")) -> Small
A3: A19DS4 | B3: Petal Perfect | C3: Asia | D3: Israel | E3: 20 | F3: 39644 | G3: =IF(YEAR(TODAY())-YEAR(DIM_FLOWERSHOPS[[#This Row],[Founded]])<=2, "A", IF(YEAR(TODAY())-YEAR(DIM_FLOWERSHOPS[[#This Row],[Founded]])<=8, "B", "C")) -> C | H3: =IF(E3<=5, "Small", IF(E3<=10, "Medium", "Large")) -> Large
A4: A20GH8 | B4: Flower Field | C4: South America | D4: Paraguay | E4: 18 | F4: 44238 | G4: =IF(YEAR(TODAY())-YEAR(DIM_FLOWERSHOPS[[#This Row],[Founded]])<=2, "A", IF(YEAR(TODAY())-YEAR(DIM_FLOWERSHOPS[[#This Row],[Founded]])<=8, "B", "C")) -> B | H4: =IF(E4<=5, "Small", IF(E4<=10, "Medium", "Large")) -> Large
A5: A50GB7 | B5: Blossom Magic | C5: Africa | D5: Kenya | E5: 16 | F5: 43203 | G5: =IF(YEAR(TODAY())-YEAR(DIM_FLOWERSHOPS[[#This Row],[Founded]])<=2, "A", IF(YEAR(TODAY())-YEAR(DIM_FLOWERSHOPS[[#This Row],[Founded]])<=8, "B", "C")) -> B | H5: =IF(E5<=5, "Small", IF(E5<=10, "Medium", "Large")) -> Large
A6: A59AS5 | B6: Blossom Garden | C6: Africa | D6: Kenya | E6: 14 | F6: 41189 | G6: =IF(YEAR(TODAY())-YEAR(DIM_FLOWERSHOPS[[#This Row],[Founded]])<=2, "A", IF(YEAR(TODAY())-YEAR(DIM_FLOWERSHOPS[[#This Row],[Founded]])<=8, "B", "C")) -> C | H6: =IF(E6<=5, "Small", IF(E6<=10, "Medium", "Large")) -> Large
A7: A66KU7 | B7: Blossom Bunch | C7: Europe | D7: Italy | E7: 5 | F7: 40119 | G7: =IF(YEAR(TODAY())-YEAR(DIM_FLOWERSHOPS[[#This Row],[Founded]])<=2, "A", IF(YEAR(TODAY())-YEAR(DIM_FLOWERSHOPS[[#This Row],[Founded]])<=8, "B", "C")) -> C | H7: =IF(E7<=5, "Small", IF(E7<=10, "Medium", "Large")) -> Small
A8: A67ZR6 | B8: Bloom Park | C8: Australia | D8: Australia | E8: 22 | F8: 44134 | G8: =IF(YEAR(TODAY())-YEAR(DIM_FLOWERSHOPS[[#This Row],[Founded]])<=2, "A", IF(YEAR(TODAY())-YEAR(DIM_FLOWERSHOPS[[#This Row],[Founded]])<=8, "B", "C")) -> B | H8: =IF(E8<=5, "Small", IF(E8<=10, "Medium", "Large")) -> Large
A9: A71FG2 | B9: Flower Patch | C9: Europe | D9: Italy | E9: 5 | F9: 41870 | G9: =IF(YEAR(TODAY())-YEAR(DIM_FLOWERSHOPS[[#This Row],[Founded]])<=2, "A", IF(YEAR(TODAY())-YEAR(DIM_FLOWERSHOPS[[#This Row],[Founded]])<=8, "B", "C")) -> C | H9: =IF(E9<=5, "Small", IF(E9<=10, "Medium", "Large")) -> Small
A10: A77AD5 | B10: Blooming Aura | C10: Asia | D10: Israel | E10: 22 | F10: 44424 | G10: =IF(YEAR(TODAY())-YEAR(DIM_FLOWERSHOPS[[#This Row],[Founded]])<=2, "A", IF(YEAR(TODAY())-YEAR(DIM_FLOWERSHOPS[[#This Row],[Founded]])<=8, "B", "C")) -> B | H10: =IF(E10<=5, "Small", IF(E10<=10, "Medium", "Large")) -> Large
A11: A92VI1 | B11: Flower Retreat | C11: Africa | D11: Kenya | E11: 3 | F11: 43002 | G11: =IF(YEAR(TODAY())-YEAR(DIM_FLOWERSHOPS[[#This Row],[Founded]])<=2, "A", IF(YEAR(TODAY())-YEAR(DIM_FLOWERSHOPS[[#This Row],[Founded]])<=8, "B", "C")) -> B | H11: =IF(E11<=5, "Small", IF(E11<=10, "Medium", "Large")) -> Small
A12: A94RT5 | B12: Flower Works | C12: Africa | D12: Kenya | E12: 6 | F12: 44236 | G12: =IF(YEAR(TODAY())-YEAR(DIM_FLOWERSHOPS[[#This Row],[Founded]])<=2, "A", IF(YEAR(TODAY())-YEAR(DIM_FLOWERSHOPS[[#This Row],[Founded]])<=8, "B", "C")) -> B | H12: =IF(E12<=5, "Small", IF(E12<=10, "Medium", "Large")) -> Medium
A13: A97YW9 | B13: Bloom Ridge | C13: Australia | D13: Fiji | E13: 20 | F13: 44411 | G13: =IF(YEAR(TODAY())-YEAR(DIM_FLOWERSHOPS[[#This Row],[Founded]])<=2, "A", IF(YEAR(TODAY())-YEAR(DIM_FLOWERSHOPS[[#This Row],[Founded]])<=8, "B", "C")) -> B | H13: =IF(E13<=5, "Small", IF(E13<=10, "Medium", "Large")) -> Large
... A421: Z96ZB3 | B421: The Flower Pavilion | C421: Africa | D421: Ethiopia | E421: 7 | F421: 41597 | G421: =IF(YEAR(TODAY())-YEAR(DIM_FLOWERSHOPS[[#This Row],[Founded]])<=2, "A", IF(YEAR(TODAY())-YEAR(DIM_FLOWERSHOPS[[#This Row],[Founded]])<=8, "B", "C")) -> C | H421: =IF(E421<=5, "Small", IF(E421<=10, "Medium", "Large")) -> Medium

Sheet DIM_PRODUCTS
A1: ProductID | B1: ProductName | C1: Category | D1: SubCategory | E1: ProductPrice | F1: DominantColor | G1: HandlingFee
A2: 0DuN4hnmeg0YtOc | B2: Aurora's Whisper | C2: {=_xlfn.IFS( OR(DIM_PRODUCTS[[#This Row],[SubCategory]]="Thanksgiving",DIM_PRODUCTS[[#This Row],[SubCategory]]="Christmas",DIM_PRODUCTS[[#This Row],[SubCategory]]="Valentines Day"),"Holidays", OR(DIM_PRODUCTS[[#This Row],[SubCategory]]="Birthday",DIM_PRODUCTS[[#This Row],[SubCategory]]="Baby Birth",DIM_PRODUCTS[[#This Row],[SubCategory]]="Marriage",DIM_PRODUCTS[[#This Row],[SubCategory]]="Anniversary",DIM_PRODUCTS[[#This Row],[SubCategory]]="Mothers Day",DIM_PRODUCTS[[#This Row],[SubCategory]]="Womans Day"),"Events", OR(DIM_PRODUCTS[[#This Row],[SubCategory]]="Summer",DIM_PRODUCTS[[#This Row],[SubCategory]]="Winter"),"Seasons", DIM_PRODUCTS[[#This Row],[SubCategory]]="Best Seller","Best Seller", TRUE,"General" )} -> Holidays | D2: Thanksgiving | E2: 274 | F2: Mixed | G2: 13.7
A3: 0hBJxuHYiAWNv7c | B3: Whispering Winds | C3: {=_xlfn.IFS( OR(DIM_PRODUCTS[[#This Row],[SubCategory]]="Thanksgiving",DIM_PRODUCTS[[#This Row],[SubCategory]]="Christmas",DIM_PRODUCTS[[#This Row],[SubCategory]]="Valentines Day"),"Holidays", OR(DIM_PRODUCTS[[#This Row],[SubCategory]]="Birthday",DIM_PRODUCTS[[#This Row],[SubCategory]]="Baby Birth",DIM_PRODUCTS[[#This Row],[SubCategory]]="Marriage",DIM_PRODUCTS[[#This Row],[SubCategory]]="Anniversary",DIM_PRODUCTS[[#This Row],[SubCategory]]="Mothers Day",DIM_PRODUCTS[[#This Row],[SubCategory]]="Womans Day"),"Events", OR(DIM_PRODUCTS[[#This Row],[SubCategory]]="Summer",DIM_PRODUCTS[[#This Row],[SubCategory]]="Winter"),"Seasons", DIM_PRODUCTS[[#This Row],[SubCategory]]="Best Seller","Best Seller", TRUE,"General" )} -> Best Seller | D3: Best Seller | E3: 172 | F3: Orange | G3: 8.6
A4: 0LGNojV8vfzp9j8 | B4: Dusk Melody | C4: {=_xlfn.IFS( OR(DIM_PRODUCTS[[#This Row],[SubCategory]]="Thanksgiving",DIM_PRODUCTS[[#This Row],[SubCategory]]="Christmas",DIM_PRODUCTS[[#This Row],[SubCategory]]="Valentines Day"),"Holidays", OR(DIM_PRODUCTS[[#This Row],[SubCategory]]="Birthday",DIM_PRODUCTS[[#This Row],[SubCategory]]="Baby Birth",DIM_PRODUCTS[[#This Row],[SubCategory]]="Marriage",DIM_PRODUCTS[[#This Row],[SubCategory]]="Anniversary",DIM_PRODUCTS[[#This Row],[SubCategory]]="Mothers Day",DIM_PRODUCTS[[#This Row],[SubCategory]]="Womans Day"),"Events", OR(DIM_PRODUCTS[[#This Row],[SubCategory]]="Summer",DIM_PRODUCTS[[#This Row],[SubCategory]]="Winter"),"Seasons", DIM_PRODUCTS[[#This Row],[SubCategory]]="Best Seller","Best Seller", TRUE,"General" )} -> Events | D4: Birthday | E4: 100.33 | F4: Pink | G4: 5.0165
A5: 0tgQD80v7jyVSTD | B5: Aromatic Cake Symphony | C5: {=_xlfn.IFS( OR(DIM_PRODUCTS[[#This Row],[SubCategory]]="Thanksgiving",DIM_PRODUCTS[[#This Row],[SubCategory]]="Christmas",DIM_PRODUCTS[[#This Row],[SubCategory]]="Valentines Day"),"Holidays", OR(DIM_PRODUCTS[[#This Row],[SubCategory]]="Birthday",DIM_PRODUCTS[[#This Row],[SubCategory]]="Baby Birth",DIM_PRODUCTS[[#This Row],[SubCategory]]="Marriage",DIM_PRODUCTS[[#This Row],[SubCategory]]="Anniversary",DIM_PRODUCTS[[#This Row],[SubCategory]]="Mothers Day",DIM_PRODUCTS[[#This Row],[SubCategory]]="Womans Day"),"Events", OR(DIM_PRODUCTS[[#This Row],[SubCategory]]="Summer",DIM_PRODUCTS[[#This Row],[SubCategory]]="Winter"),"Seasons", DIM_PRODUCTS[[#This Row],[SubCategory]]="Best Seller","Best Seller", TRUE,"General" )} -> Holidays | D5: Thanksgiving | E5: 191.8 | F5: Mixed | G5: 9.59
A6: 0zxjZXhT6mrSVwd | B6: Tender Feelings | C6: {=_xlfn.IFS( OR(DIM_PRODUCTS[[#This Row],[SubCategory]]="Thanksgiving",DIM_PRODUCTS[[#This Row],[SubCategory]]="Christmas",DIM_PRODUCTS[[#This Row],[SubCategory]]="Valentines Day"),"Holidays", OR(DIM_PRODUCTS[[#This Row],[SubCategory]]="Birthday",DIM_PRODUCTS[[#This Row],[SubCategory]]="Baby Birth",DIM_PRODUCTS[[#This Row],[SubCategory]]="Marriage",DIM_PRODUCTS[[#This Row],[SubCategory]]="Anniversary",DIM_PRODUCTS[[#This Row],[SubCategory]]="Mothers Day",DIM_PRODUCTS[[#This Row],[SubCategory]]="Womans Day"),"Events", OR(DIM_PRODUCTS[[#This Row],[SubCategory]]="Summer",DIM_PRODUCTS[[#This Row],[SubCategory]]="Winter"),"Seasons", DIM_PRODUCTS[[#This Row],[SubCategory]]="Best Seller","Best Seller", TRUE,"General" )} -> Events | D6: Anniversary | E6: 267 | F6: White | G6: 13.35
A7: 1356EYlpwpoBKjw | B7: Eternal Love | C7: {=_xlfn.IFS( OR(DIM_PRODUCTS[[#This Row],[SubCategory]]="Thanksgiving",DIM_PRODUCTS[[#This Row],[SubCategory]]="Christmas",DIM_PRODUCTS[[#This Row],[SubCategory]]="Valentines Day"),"Holidays", OR(DIM_PRODUCTS[[#This Row],[SubCategory]]="Birthday",DIM_PRODUCTS[[#This Row],[SubCategory]]="Baby Birth",DIM_PRODUCTS[[#This Row],[SubCategory]]="Marriage",DIM_PRODUCTS[[#This Row],[SubCategory]]="Anniversary",DIM_PRODUCTS[[#This Row],[SubCategory]]="Mothers Day",DIM_PRODUCTS[[#This Row],[SubCategory]]="Womans Day"),"Events", OR(DIM_PRODUCTS[[#This Row],[SubCategory]]="Summer",DIM_PRODUCTS[[#This Row],[SubCategory]]="Winter"),"Seasons", DIM_PRODUCTS[[#This Row],[SubCategory]]="Best Seller","Best Seller", TRUE,"General" )} -> General | D7: Im Sorry | E7: 249 | F7: Mixed | G7: 12.45
A8: 13woLJG0HaIaM2k | B8: White and Red Roses Bouquet Serenade | C8: {=_xlfn.IFS( OR(DIM_PRODUCTS[[#This Row],[SubCategory]]="Thanksgiving",DIM_PRODUCTS[[#This Row],[SubCategory]]="Christmas",DIM_PRODUCTS[[#This Row],[SubCategory]]="Valentines Day"),"Holidays", OR(DIM_PRODUCTS[[#This Row],[SubCategory]]="Birthday",DIM_PRODUCTS[[#This Row],[SubCategory]]="Baby Birth",DIM_PRODUCTS[[#This Row],[SubCategory]]="Marriage",DIM_PRODUCTS[[#This Row],[SubCategory]]="Anniversary",DIM_PRODUCTS[[#This Row],[SubCategory]]="Mothers Day",DIM_PRODUCTS[[#This Row],[SubCategory]]="Womans Day"),"Events", OR(DIM_PRODUCTS[[#This Row],[SubCategory]]="Summer",DIM_PRODUCTS[[#This Row],[SubCategory]]="Winter"),"Seasons", DIM_PRODUCTS[[#This Row],[SubCategory]]="Best Seller","Best Seller", TRUE,"General" )} -> Events | D8: Anniversary | E8: 81 | F8: White | G8: 4.05
A9: 175q1k2iZ2p45oK | B9: Enchanted Sunset | C9: {=_xlfn.IFS( OR(DIM_PRODUCTS[[#This Row],[SubCategory]]="Thanksgiving",DIM_PRODUCTS[[#This Row],[SubCategory]]="Christmas",DIM_PRODUCTS[[#This Row],[SubCategory]]="Valentines Day"),"Holidays", OR(DIM_PRODUCTS[[#This Row],[SubCategory]]="Birthday",DIM_PRODUCTS[[#This Row],[SubCategory]]="Baby Birth",DIM_PRODUCTS[[#This Row],[SubCategory]]="Marriage",DIM_PRODUCTS[[#This Row],[SubCategory]]="Anniversary",DIM_PRODUCTS[[#This Row],[SubCategory]]="Mothers Day",DIM_PRODUCTS[[#This Row],[SubCategory]]="Womans Day"),"Events", OR(DIM_PRODUCTS[[#This Row],[SubCategory]]="Summer",DIM_PRODUCTS[[#This Row],[SubCategory]]="Winter"),"Seasons", DIM_PRODUCTS[[#This Row],[SubCategory]]="Best Seller","Best Seller", TRUE,"General" )} -> General | D9: Thank You | E9: 84 | F9: Lavender | G9: 4.2
A10: 1GMU01K3qgwjt4R | B10: Harmony's Embrace | C10: {=_xlfn.IFS( OR(DIM_PRODUCTS[[#This Row],[SubCategory]]="Thanksgiving",DIM_PRODUCTS[[#This Row],[SubCategory]]="Christmas",DIM_PRODUCTS[[#This Row],[SubCategory]]="Valentines Day"),"Holidays", OR(DIM_PRODUCTS[[#This Row],[SubCategory]]="Birthday",DIM_PRODUCTS[[#This Row],[SubCategory]]="Baby Birth",DIM_PRODUCTS[[#This Row],[SubCategory]]="Marriage",DIM_PRODUCTS[[#This Row],[SubCategory]]="Anniversary",DIM_PRODUCTS[[#This Row],[SubCategory]]="Mothers Day",DIM_PRODUCTS[[#This Row],[SubCategory]]="Womans Day"),"Events", OR(DIM_PRODUCTS[[#This Row],[SubCategory]]="Summer",DIM_PRODUCTS[[#This Row],[SubCategory]]="Winter"),"Seasons", DIM_PRODUCTS[[#This Row],[SubCategory]]="Best Seller","Best Seller", TRUE,"General" )} -> Events | D10: Mothers Day | E10: 238 | F10: Light Pink | G10: 11.9
A11: 1gsbgJDQ40kIfPe | B11: Twilight Whispers | C11: {=_xlfn.IFS( OR(DIM_PRODUCTS[[#This Row],[SubCategory]]="Thanksgiving",DIM_PRODUCTS[[#This Row],[SubCategory]]="Christmas",DIM_PRODUCTS[[#This Row],[SubCategory]]="Valentines Day"),"Holidays", OR(DIM_PRODUCTS[[#This Row],[SubCategory]]="Birthday",DIM_PRODUCTS[[#This Row],[SubCategory]]="Baby Birth",DIM_PRODUCTS[[#This Row],[SubCategory]]="Marriage",DIM_PRODUCTS[[#This Row],[SubCategory]]="Anniversary",DIM_PRODUCTS[[#This Row],[SubCategory]]="Mothers Day",DIM_PRODUCTS[[#This Row],[SubCategory]]="Womans Day"),"Events", OR(DIM_PRODUCTS[[#This Row],[SubCategory]]="Summer",DIM_PRODUCTS[[#This Row],[SubCategory]]="Winter"),"Seasons", DIM_PRODUCTS[[#This Row],[SubCategory]]="Best Seller","Best Seller", TRUE,"General" )} -> Holidays | D11: Valentines Day | E11: 273 | F11: Red | G11: 13.65
A12: 1HkaqausShOW6XN | B12: Flamingo's Serenade | C12: {=_xlfn.IFS( OR(DIM_PRODUCTS[[#This Row],[SubCategory]]="Thanksgiving",DIM_PRODUCTS[[#This Row],[SubCategory]]="Christmas",DIM_PRODUCTS[[#This Row],[SubCategory]]="Valentines Day"),"Holidays", OR(DIM_PRODUCTS[[#This Row],[SubCategory]]="Birthday",DIM_PRODUCTS[[#This Row],[SubCategory]]="Baby Birth",DIM_PRODUCTS[[#This Row],[SubCategory]]="Marriage",DIM_PRODUCTS[[#This Row],[SubCategory]]="Anniversary",DIM_PRODUCTS[[#This Row],[SubCategory]]="Mothers Day",DIM_PRODUCTS[[#This Row],[SubCategory]]="Womans Day"),"Events", OR(DIM_PRODUCTS[[#This Row],[SubCategory]]="Summer",DIM_PRODUCTS[[#This Row],[SubCategory]]="Winter"),"Seasons", DIM_PRODUCTS[[#This Row],[SubCategory]]="Best Seller","Best Seller", TRUE,"General" )} -> Events | D12: Womans Day | E12: 65 | F12: Magenta | G12: 3.25
A13: 1jFpHrM5Bd8LsMT | B13: Tranquil Elegance | C13: {=_xlfn.IFS( OR(DIM_PRODUCTS[[#This Row],[SubCategory]]="Thanksgiving",DIM_PRODUCTS[[#This Row],[SubCategory]]="Christmas",DIM_PRODUCTS[[#This Row],[SubCategory]]="Valentines Day"),"Holidays", OR(DIM_PRODUCTS[[#This Row],[SubCategory]]="Birthday",DIM_PRODUCTS[[#This Row],[SubCategory]]="Baby Birth",DIM_PRODUCTS[[#This Row],[SubCategory]]="Marriage",DIM_PRODUCTS[[#This Row],[SubCategory]]="Anniversary",DIM_PRODUCTS[[#This Row],[SubCategory]]="Mothers Day",DIM_PRODUCTS[[#This Row],[SubCategory]]="Womans Day"),"Events", OR(DIM_PRODUCTS[[#This Row],[SubCategory]]="Summer",DIM_PRODUCTS[[#This Row],[SubCategory]]="Winter"),"Seasons", DIM_PRODUCTS[[#This Row],[SubCategory]]="Best Seller","Best Seller", TRUE,"General" )} -> Best Seller | D13: Best Seller | E13: 89 | F13: Orange | G13: 4.45
... A526: zyuli7BcdrAqU53 | B526: Velvet Sky | C526: {=_xlfn.IFS( OR(DIM_PRODUCTS[[#This Row],[SubCategory]]="Thanksgiving",DIM_PRODUCTS[[#This Row],[SubCategory]]="Christmas",DIM_PRODUCTS[[#This Row],[SubCategory]]="Valentines Day"),"Holidays", OR(DIM_PRODUCTS[[#This Row],[SubCategory]]="Birthday",DIM_PRODUCTS[[#This Row],[SubCategory]]="Baby Birth",DIM_PRODUCTS[[#This Row],[SubCategory]]="Marriage",DIM_PRODUCTS[[#This Row],[SubCategory]]="Anniversary",DIM_PRODUCTS[[#This Row],[SubCategory]]="Mothers Day",DIM_PRODUCTS[[#This Row],[SubCategory]]="Womans Day"),"Events", OR(DIM_PRODUCTS[[#This Row],[SubCategory]]="Summer",DIM_PRODUCTS[[#This Row],[SubCategory]]="Winter"),"Seasons", DIM_PRODUCTS[[#This Row],[SubCategory]]="Best Seller","Best Seller", TRUE,"General" )} -> General | D526: Im Sorry | E526: 250 | F526: Mixed | G526: 12.5

Sheet FACT_ORDERS
A1: DW Order | B1: OrderID | C1: ShopID | D1: ProductID | E1: Quantity | F1: Email | G1: OrderDate | H1: Country | I1: DeliveryDate | J1: Rating | K1: IsOnTime | L1: DeliveryFee | M1: DeliveryCost | N1: TotalPricePerProduct | O1: TotalRevenuePerProduct | P1: OperationsCost
A2: 1 | B2: Kriyp7 | C2: A50GB7 | D2: 1gsbgJDQ40kIfPe | E2: 1 | F2: egatesman8x@washingtonpost.com | G2: 45471 | H2: Kenya | I2: 45474 | J2: =_xlfn.XLOOKUP(B2,ORDERS[OrderID],ORDERS[Rating],"Null") -> 5 | K2: =IF(FACT_ORDERS[[#This Row],[DeliveryDate]]-FACT_ORDERS[[#This Row],[OrderDate]]<=1,1,0) -> 0 | L2: 15 | M2: =(FACT_ORDERS[[#This Row],[Quantity]]/SUMIF(B$1:B$1643,FACT_ORDERS[[#This Row],[OrderID]],E$1:E$1643))*IF(SUMIFS(FACT_ORDERS[Quantity], FACT_ORDERS[OrderID], FACT_ORDERS[[#This Row],[OrderID]]) < 5, 15, IF(SUMIFS(FACT_ORDERS[Quantity], FACT_ORDERS[OrderID], FACT_ORDERS[[#This Row],[OrderID]]) <= 10, 12, 10)) -> 15 | N2: =(_xlfn.XLOOKUP(D2,DIM_PRODUCTS[ProductID],DIM_PRODUCTS[HandlingFee]))*FACT_ORDERS[[#This Row],[Quantity]] + FACT_ORDERS[[#This Row],[DeliveryFee]] -> 28.65 | O2: =FACT_ORDERS[[#This Row],[TotalPricePerProduct]]-FACT_ORDERS[[#This Row],[DeliveryCost]]-FACT_ORDERS[[#This Row],[OperationsCost]] -> 6.65 | P2: 7
A3: 2 | B3: Okb3JP | C3: A59AS5 | D3: KqgWBGYUcKmaR6g | E3: 2 | F3: mreede6v@discuz.net | G3: 45394 | H3: Kenya | I3: 45394 | J3: =_xlfn.XLOOKUP(B3,ORDERS[OrderID],ORDERS[Rating],"Null") -> 3 | K3: =IF(FACT_ORDERS[[#This Row],[DeliveryDate]]-FACT_ORDERS[[#This Row],[OrderDate]]<=1,1,0) -> 1 | L3: 15 | M3: =(FACT_ORDERS[[#This Row],[Quantity]]/SUMIF(B$1:B$1643,FACT_ORDERS[[#This Row],[OrderID]],E$1:E$1643))*IF(SUMIFS(FACT_ORDERS[Quantity], FACT_ORDERS[OrderID], FACT_ORDERS[[#This Row],[OrderID]]) < 5, 15, IF(SUMIFS(FACT_ORDERS[Quantity], FACT_ORDERS[OrderID], FACT_ORDERS[[#This Row],[OrderID]]) <= 10, 12, 10)) -> 15 | N3: =(_xlfn.XLOOKUP(D3,DIM_PRODUCTS[ProductID],DIM_PRODUCTS[HandlingFee]))*FACT_ORDERS[[#This Row],[Quantity]] + FACT_ORDERS[[#This Row],[DeliveryFee]] -> 29.5 | O3: =FACT_ORDERS[[#This Row],[TotalPricePerProduct]]-FACT_ORDERS[[#This Row],[DeliveryCost]]-FACT_ORDERS[[#This Row],[OperationsCost]] -> 5.5 | P3: 9
A4: 3 | B4: zqbUWE | C4: A66KU7 | D4: g5KsLwDER4h3IZt | E4: 2 | F4: tewols5x@tumblr.com | G4: 45198 | H4: Italy | I4: 45198 | J4: =_xlfn.XLOOKUP(B4,ORDERS[OrderID],ORDERS[Rating],"Null") -> 4 | K4: =IF(FACT_ORDERS[[#This Row],[DeliveryDate]]-FACT_ORDERS[[#This Row],[OrderDate]]<=1,1,0) -> 1 | L4: 15 | M4: =(FACT_ORDERS[[#This Row],[Quantity]]/SUMIF(B$1:B$1643,FACT_ORDERS[[#This Row],[OrderID]],E$1:E$1643))*IF(SUMIFS(FACT_ORDERS[Quantity], FACT_ORDERS[OrderID], FACT_ORDERS[[#This Row],[OrderID]]) < 5, 15, IF(SUMIFS(FACT_ORDERS[Quantity], FACT_ORDERS[OrderID], FACT_ORDERS[[#This Row],[OrderID]]) <= 10, 12, 10)) -> 15 | N4: =(_xlfn.XLOOKUP(D4,DIM_PRODUCTS[ProductID],DIM_PRODUCTS[HandlingFee]))*FACT_ORDERS[[#This Row],[Quantity]] + FACT_ORDERS[[#This Row],[DeliveryFee]] -> 32.1 | O4: =FACT_ORDERS[[#This Row],[TotalPricePerProduct]]-FACT_ORDERS[[#This Row],[DeliveryCost]]-FACT_ORDERS[[#This Row],[OperationsCost]] -> 4.1 | P4: 13
A5: 4 | B5: PSakyg | C5: A66KU7 | D5: g5KsLwDER4h3IZt | E5: 2 | F5: rgoodisona3@shutterfly.com | G5: 45474 | H5: Italy | I5: 45474 | J5: =_xlfn.XLOOKUP(B5,ORDERS[OrderID],ORDERS[Rating],"Null") -> 1 | K5: =IF(FACT_ORDERS[[#This Row],[DeliveryDate]]-FACT_ORDERS[[#This Row],[OrderDate]]<=1,1,0) -> 1 | L5: 15 | M5: =(FACT_ORDERS[[#This Row],[Quantity]]/SUMIF(B$1:B$1643,FACT_ORDERS[[#This Row],[OrderID]],E$1:E$1643))*IF(SUMIFS(FACT_ORDERS[Quantity], FACT_ORDERS[OrderID], FACT_ORDERS[[#This Row],[OrderID]]) < 5, 15, IF(SUMIFS(FACT_ORDERS[Quantity], FACT_ORDERS[OrderID], FACT_ORDERS[[#This Row],[OrderID]]) <= 10, 12, 10)) -> 15 | N5: =(_xlfn.XLOOKUP(D5,DIM_PRODUCTS[ProductID],DIM_PRODUCTS[HandlingFee]))*FACT_ORDERS[[#This Row],[Quantity]] + FACT_ORDERS[[#This Row],[DeliveryFee]] -> 32.1 | O5: =FACT_ORDERS[[#This Row],[TotalPricePerProduct]]-FACT_ORDERS[[#This Row],[DeliveryCost]]-FACT_ORDERS[[#This Row],[OperationsCost]] -> -1.9 | P5: 19
A6: 5 | B6: 6ahfL6 | C6: A67ZR6 | D6: 50Gnx1DQIOVsJht | E6: 5 | F6: emcgairl6m@springer.com | G6: 45235 | H6: Australia | I6: 45235 | J6: =_xlfn.XLOOKUP(B6,ORDERS[OrderID],ORDERS[Rating],"Null") -> 5 | K6: =IF(FACT_ORDERS[[#This Row],[DeliveryDate]]-FACT_ORDERS[[#This Row],[OrderDate]]<=1,1,0) -> 1 | L6: 12.5 | M6: =(FACT_ORDERS[[#This Row],[Quantity]]/SUMIF(B$1:B$1643,FACT_ORDERS[[#This Row],[OrderID]],E$1:E$1643))*IF(SUMIFS(FACT_ORDERS[Quantity], FACT_ORDERS[OrderID], FACT_ORDERS[[#This Row],[OrderID]]) < 5, 15, IF(SUMIFS(FACT_ORDERS[Quantity], FACT_ORDERS[OrderID], FACT_ORDERS[[#This Row],[OrderID]]) <= 10, 12, 10)) -> 10 | N6: =(_xlfn.XLOOKUP(D6,DIM_PRODUCTS[ProductID],DIM_PRODUCTS[HandlingFee]))*FACT_ORDERS[[#This Row],[Quantity]] + FACT_ORDERS[[#This Row],[DeliveryFee]] -> 70.75 | O6: =FACT_ORDERS[[#This Row],[TotalPricePerProduct]]-FACT_ORDERS[[#This Row],[DeliveryCost]]-FACT_ORDERS[[#This Row],[OperationsCost]] -> 47.75 | P6: 13
A7: 6 | B7: HoYScX | C7: A67ZR6 | D7: 50Gnx1DQIOVsJht | E7: 7 | F7: oyakovitch6y@fda.gov | G7: 45214 | H7: Australia | I7: 45214 | J7: =_xlfn.XLOOKUP(B7,ORDERS[OrderID],ORDERS[Rating],"Null") -> 2 | K7: =IF(FACT_ORDERS[[#This Row],[DeliveryDate]]-FACT_ORDERS[[#This Row],[OrderDate]]<=1,1,0) -> 1 | L7: 4.0384615 | M7: =(FACT_ORDERS[[#This Row],[Quantity]]/SUMIF(B$1:B$1643,FACT_ORDERS[[#This Row],[OrderID]],E$1:E$1643))*IF(SUMIFS(FACT_ORDERS[Quantity], FACT_ORDERS[OrderID], FACT_ORDERS[[#This Row],[OrderID]]) < 5, 15, IF(SUMIFS(FACT_ORDERS[Quantity], FACT_ORDERS[OrderID], FACT_ORDERS[[#This Row],[OrderID]]) <= 10, 12, 10)) -> 2.6923077 | N7: =(_xlfn.XLOOKUP(D7,DIM_PRODUCTS[ProductID],DIM_PRODUCTS[HandlingFee]))*FACT_ORDERS[[#This Row],[Quantity]] + FACT_ORDERS[[#This Row],[DeliveryFee]] -> 85.588462 | O7: =FACT_ORDERS[[#This Row],[TotalPricePerProduct]]-FACT_ORDERS[[#This Row],[DeliveryCost]]-FACT_ORDERS[[#This Row],[OperationsCost]] -> 69.896154 | P7: 13
A8: 7 | B8: 6ahfL6 | C8: A67ZR6 | D8: XwmJWdf4CDYF62x | E8: 1 | F8: emcgairl6m@springer.com | G8: 45235 | H8: Australia | I8: 45235 | J8: =_xlfn.XLOOKUP(B8,ORDERS[OrderID],ORDERS[Rating],"Null") -> 5 | K8: =IF(FACT_ORDERS[[#This Row],[DeliveryDate]]-FACT_ORDERS[[#This Row],[OrderDate]]<=1,1,0) -> 1 | L8: 2.5 | M8: =(FACT_ORDERS[[#This Row],[Quantity]]/SUMIF(B$1:B$1643,FACT_ORDERS[[#This Row],[OrderID]],E$1:E$1643))*IF(SUMIFS(FACT_ORDERS[Quantity], FACT_ORDERS[OrderID], FACT_ORDERS[[#This Row],[OrderID]]) < 5, 15, IF(SUMIFS(FACT_ORDERS[Quantity], FACT_ORDERS[OrderID], FACT_ORDERS[[#This Row],[OrderID]]) <= 10, 12, 10)) -> 2 | N8: =(_xlfn.XLOOKUP(D8,DIM_PRODUCTS[ProductID],DIM_PRODUCTS[HandlingFee]))*FACT_ORDERS[[#This Row],[Quantity]] + FACT_ORDERS[[#This Row],[DeliveryFee]] -> 14.35 | O8: =FACT_ORDERS[[#This Row],[TotalPricePerProduct]]-FACT_ORDERS[[#This Row],[DeliveryCost]]-FACT_ORDERS[[#This Row],[OperationsCost]] -> 4.35 | P8: 8
A9: 8 | B9: HoYScX | C9: A67ZR6 | D9: XwmJWdf4CDYF62x | E9: 11 | F9: oyakovitch6y@fda.gov | G9: 45214 | H9: Australia | I9: 45214 | J9: =_xlfn.XLOOKUP(B9,ORDERS[OrderID],ORDERS[Rating],"Null") -> 2 | K9: =IF(FACT_ORDERS[[#This Row],[DeliveryDate]]-FACT_ORDERS[[#This Row],[OrderDate]]<=1,1,0) -> 1 | L9: 6.3461538 | M9: =(FACT_ORDERS[[#This Row],[Quantity]]/SUMIF(B$1:B$1643,FACT_ORDERS[[#This Row],[OrderID]],E$1:E$1643))*IF(SUMIFS(FACT_ORDERS[Quantity], FACT_ORDERS[OrderID], FACT_ORDERS[[#This Row],[OrderID]]) < 5, 15, IF(SUMIFS(FACT_ORDERS[Quantity], FACT_ORDERS[OrderID], FACT_ORDERS[[#This Row],[OrderID]]) <= 10, 12, 10)) -> 4.2307692 | N9: =(_xlfn.XLOOKUP(D9,DIM_PRODUCTS[ProductID],DIM_PRODUCTS[HandlingFee]))*FACT_ORDERS[[#This Row],[Quantity]] + FACT_ORDERS[[#This Row],[DeliveryFee]] -> 136.69615 | O9: =FACT_ORDERS[[#This Row],[TotalPricePerProduct]]-FACT_ORDERS[[#This Row],[DeliveryCost]]-FACT_ORDERS[[#This Row],[OperationsCost]] -> 116.46538 | P9: 16
A10: 9 | B10: LWnLu3 | C10: A67ZR6 | D10: 50Gnx1DQIOVsJht | E10: 1 | F10: jcockerham54@photobucket.com | G10: 45212 | H10: Australia | I10: 45212 | J10: =_xlfn.XLOOKUP(B10,ORDERS[OrderID],ORDERS[Rating],"Null") -> 3 | K10: =IF(FACT_ORDERS[[#This Row],[DeliveryDate]]-FACT_ORDERS[[#This Row],[OrderDate]]<=1,1,0) -> 1 | L10: 3.75 | M10: =(FACT_ORDERS[[#This Row],[Quantity]]/SUMIF(B$1:B$1643,FACT_ORDERS[[#This Row],[OrderID]],E$1:E$1643))*IF(SUMIFS(FACT_ORDERS[Quantity], FACT_ORDERS[OrderID], FACT_ORDERS[[#This Row],[OrderID]]) < 5, 15, IF(SUMIFS(FACT_ORDERS[Quantity], FACT_ORDERS[OrderID], FACT_ORDERS[[#This Row],[OrderID]]) <= 10, 12, 10)) -> 3.75 | N10: =(_xlfn.XLOOKUP(D10,DIM_PRODUCTS[ProductID],DIM_PRODUCTS[HandlingFee]))*FACT_ORDERS[[#This Row],[Quantity]] + FACT_ORDERS[[#This Row],[DeliveryFee]] -> 15.4 | O10: =FACT_ORDERS[[#This Row],[TotalPricePerProduct]]-FACT_ORDERS[[#This Row],[DeliveryCost]]-FACT_ORDERS[[#This Row],[OperationsCost]] -> -0.35 | P10: 12
A11: 10 | B11: 45UbCx | C11: A67ZR6 | D11: 50Gnx1DQIOVsJht | E11: 10 | F11: ecompson9@youtube.com | G11: 45148 | H11: Australia | I11: 45148 | J11: =_xlfn.XLOOKUP(B11,ORDERS[OrderID],ORDERS[Rating],"Null") -> 4 | K11: =IF(FACT_ORDERS[[#This Row],[DeliveryDate]]-FACT_ORDERS[[#This Row],[OrderDate]]<=1,1,0) -> 1 | L11: 15 | M11: =(FACT_ORDERS[[#This Row],[Quantity]]/SUMIF(B$1:B$1643,FACT_ORDERS[[#This Row],[OrderID]],E$1:E$1643))*IF(SUMIFS(FACT_ORDERS[Quantity], FACT_ORDERS[OrderID], FACT_ORDERS[[#This Row],[OrderID]]) < 5, 15, IF(SUMIFS(FACT_ORDERS[Quantity], FACT_ORDERS[OrderID], FACT_ORDERS[[#This Row],[OrderID]]) <= 10, 12, 10)) -> 12 | N11: =(_xlfn.XLOOKUP(D11,DIM_PRODUCTS[ProductID],DIM_PRODUCTS[HandlingFee]))*FACT_ORDERS[[#This Row],[Quantity]] + FACT_ORDERS[[#This Row],[DeliveryFee]] -> 131.5 | O11: =FACT_ORDERS[[#This Row],[TotalPricePerProduct]]-FACT_ORDERS[[#This Row],[DeliveryCost]]-FACT_ORDERS[[#This Row],[OperationsCost]] -> 100.5 | P11: 19
A12: 11 | B12: ugk7Vx | C12: A77AD5 | D12: b7CQBhUIcw9Myn4 | E12: 5 | F12: mvasyunin7h@hexun.com | G12: 45267 | H12: Israel | I12: 45268 | J12: =_xlfn.XLOOKUP(B12,ORDERS[OrderID],ORDERS[Rating],"Null") -> 4 | K12: =IF(FACT_ORDERS[[#This Row],[DeliveryDate]]-FACT_ORDERS[[#This Row],[OrderDate]]<=1,1,0) -> 1 | L12: 4.1666667 | M12: =(FACT_ORDERS[[#This Row],[Quantity]]/SUMIF(B$1:B$1643,FACT_ORDERS[[#This Row],[OrderID]],E$1:E$1643))*IF(SUMIFS(FACT_ORDERS[Quantity], FACT_ORDERS[OrderID], FACT_ORDERS[[#This Row],[OrderID]]) < 5, 15, IF(SUMIFS(FACT_ORDERS[Quantity], FACT_ORDERS[OrderID], FACT_ORDERS[[#This Row],[OrderID]]) <= 10, 12, 10)) -> 2.7777778 | N12: =(_xlfn.XLOOKUP(D12,DIM_PRODUCTS[ProductID],DIM_PRODUCTS[HandlingFee]))*FACT_ORDERS[[#This Row],[Quantity]] + FACT_ORDERS[[#This Row],[DeliveryFee]] -> 70.916667 | O12: =FACT_ORDERS[[#This Row],[TotalPricePerProduct]]-FACT_ORDERS[[#This Row],[DeliveryCost]]-FACT_ORDERS[[#This Row],[OperationsCost]] -> 49.138889 | P12: 19
A13: 12 | B13: ugk7Vx | C13: A77AD5 | D13: HW0gDAf8Jxb6HEB | E13: 2 | F13: mvasyunin7h@hexun.com | G13: 45267 | H13: Israel | I13: 45268 | J13: =_xlfn.XLOOKUP(B13,ORDERS[OrderID],ORDERS[Rating],"Null") -> 4 | K13: =IF(FACT_ORDERS[[#This Row],[DeliveryDate]]-FACT_ORDERS[[#This Row],[OrderDate]]<=1,1,0) -> 1 | L13: 1.6666667 | M13: =(FACT_ORDERS[[#This Row],[Quantity]]/SUMIF(B$1:B$1643,FACT_ORDERS[[#This Row],[OrderID]],E$1:E$1643))*IF(SUMIFS(FACT_ORDERS[Quantity], FACT_ORDERS[OrderID], FACT_ORDERS[[#This Row],[OrderID]]) < 5, 15, IF(SUMIFS(FACT_ORDERS[Quantity], FACT_ORDERS[OrderID], FACT_ORDERS[[#This Row],[OrderID]]) <= 10, 12, 10)) -> 1.1111111 | N13: =(_xlfn.XLOOKUP(D13,DIM_PRODUCTS[ProductID],DIM_PRODUCTS[HandlingFee]))*FACT_ORDERS[[#This Row],[Quantity]] + FACT_ORDERS[[#This Row],[DeliveryFee]] -> 24.166667 | O13: =FACT_ORDERS[[#This Row],[TotalPricePerProduct]]-FACT_ORDERS[[#This Row],[DeliveryCost]]-FACT_ORDERS[[#This Row],[OperationsCost]] -> 4.0555556 | P13: 19
... A15: 14 | B15: OdSnkb | C15: A92VI1 | D15: 7a2YxxKsvgmV7Ee | E15: 9 | F15: scalderon94@google.com.hk | G15: 45419 | H15: Kenya | I15: 45422 | J15: =_xlfn.XLOOKUP(B15,ORDERS[OrderID],ORDERS[Rating],"Null") -> 4 | K15: =IF(FACT_ORDERS[[#This Row],[DeliveryDate]]-FACT_ORDERS[[#This Row],[OrderDate]]<=1,1,0) -> 0 | L15: 7.9411765 | M15: =(FACT_ORDERS[[#This Row],[Quantity]]/SUMIF(B$1:B$1643,FACT_ORDERS[[#This Row],[OrderID]],E$1:E$1643))*IF(SUMIFS(FACT_ORDERS[Quantity], FACT_ORDERS[OrderID], FACT_ORDERS[[#This Row],[OrderID]]) < 5, 15, IF(SUMIFS(FACT_ORDERS[Quantity], FACT_ORDERS[OrderID], FACT_ORDERS[[#This Row],[OrderID]]) <= 10, 12, 10)) -> 5.2941176 | N15: =(_xlfn.XLOOKUP(D15,DIM_PRODUCTS[ProductID],DIM_PRODUCTS[HandlingFee]))*FACT_ORDERS[[#This Row],[Quantity]] + FACT_ORDERS[[#This Row],[DeliveryFee]] -> 52.491176 | O15: =FACT_ORDERS[[#This Row],[TotalPricePerProduct]]-FACT_ORDERS[[#This Row],[DeliveryCost]]-FACT_ORDERS[[#This Row],[OperationsCost]] -> 40.197059 | P15: 7
A16: 15 | B16: 33280 | C16: A94RT5 | D16: e43l7i5ZF9FHVXv | E16: 6 | F16: renevoldsen5y@nydailynews.com | G16: 45206 | H16: Kenya | I16: 45208 | J16: =_xlfn.XLOOKUP(B16,ORDERS[OrderID],ORDERS[Rating],"Null") -> 4 | K16: =IF(FACT_ORDERS[[#This Row],[DeliveryDate]]-FACT_ORDERS[[#This Row],[OrderDate]]<=1,1,0) -> 0 | L16: 15 | M16: =(FACT_ORDERS[[#This Row],[Quantity]]/SUMIF(B$1:B$1643,FACT_ORDERS[[#This Row],[OrderID]],E$1:E$1643))*IF(SUMIFS(FACT_ORDERS[Quantity], FACT_ORDERS[OrderID], FACT_ORDERS[[#This Row],[OrderID]]) < 5, 15, IF(SUMIFS(FACT_ORDERS[Quantity], FACT_ORDERS[OrderID], FACT_ORDERS[[#This Row],[OrderID]]) <= 10, 12, 10)) -> 12 | N16: =(_xlfn.XLOOKUP(D16,DIM_PRODUCTS[ProductID],DIM_PRODUCTS[HandlingFee]))*FACT_ORDERS[[#This Row],[Quantity]] + FACT_ORDERS[[#This Row],[DeliveryFee]] -> 43.644 | O16: =FACT_ORDERS[[#This Row],[TotalPricePerProduct]]-FACT_ORDERS[[#This Row],[DeliveryCost]]-FACT_ORDERS[[#This Row],[OperationsCost]] -> 15.644 | P16: 16
A17: 16 | B17: 4IZK9BD8QNJ | C17: B21VD0 | D17: x58z3a1dMUKllwp | E17: 7 | F17: mjeandel2p@arizona.edu | G17: 45139 | H17: Fiji | I17: 45139 | J17: =_xlfn.XLOOKUP(B17,ORDERS[OrderID],ORDERS[Rating],"Null") -> 5 | K17: =IF(FACT_ORDERS[[#This Row],[DeliveryDate]]-FACT_ORDERS[[#This Row],[OrderDate]]<=1,1,0) -> 1 | L17: 15 | M17: =(FACT_ORDERS[[#This Row],[Quantity]]/SUMIF(B$1:B$1643,FACT_ORDERS[[#This Row],[OrderID]],E$1:E$1643))*IF(SUMIFS(FACT_ORDERS[Quantity], FACT_ORDERS[OrderID], FACT_ORDERS[[#This Row],[OrderID]]) < 5, 15, IF(SUMIFS(FACT_ORDERS[Quantity], FACT_ORDERS[OrderID], FACT_ORDERS[[#This Row],[OrderID]]) <= 10, 12, 10)) -> 12 | N17: =(_xlfn.XLOOKUP(D17,DIM_PRODUCTS[ProductID],DIM_PRODUCTS[HandlingFee]))*FACT_ORDERS[[#This Row],[Quantity]] + FACT_ORDERS[[#This Row],[DeliveryFee]] -> 117.55 | O17: =FACT_ORDERS[[#This Row],[TotalPricePerProduct]]-FACT_ORDERS[[#This Row],[DeliveryCost]]-FACT_ORDERS[[#This Row],[OperationsCost]] -> 94.55 | P17: 11
A18: 17 | B18: zJr5Bv | C18: B47KD7 | D18: vgaH0vu1xrL7S2D | E18: 8 | F18: cpezey8q@msn.com | G18: 45245 | H18: Guatemala | I18: 45245 | J18: =_xlfn.XLOOKUP(B18,ORDERS[OrderID],ORDERS[Rating],"Null") -> 4 | K18: =IF(FACT_ORDERS[[#This Row],[DeliveryDate]]-FACT_ORDERS[[#This Row],[OrderDate]]<=1,1,0) -> 1 | L18: 15 | M18: =(FACT_ORDERS[[#This Row],[Quantity]]/SUMIF(B$1:B$1643,FACT_ORDERS[[#This Row],[OrderID]],E$1:E$1643))*IF(SUMIFS(FACT_ORDERS[Quantity], FACT_ORDERS[OrderID], FACT_ORDERS[[#This Row],[OrderID]]) < 5, 15, IF(SUMIFS(FACT_ORDERS[Quantity], FACT_ORDERS[OrderID], FACT_ORDERS[[#This Row],[OrderID]]) <= 10, 12, 10)) -> 12 | N18: =(_xlfn.XLOOKUP(D18,DIM_PRODUCTS[ProductID],DIM_PRODUCTS[HandlingFee]))*FACT_ORDERS[[#This Row],[Quantity]] + FACT_ORDERS[[#This Row],[DeliveryFee]] -> 89.4 | O18: =FACT_ORDERS[[#This Row],[TotalPricePerProduct]]-FACT_ORDERS[[#This Row],[DeliveryCost]]-FACT_ORDERS[[#This Row],[OperationsCost]] -> 59.4 | P18: 18
A19: 18 | B19: 7zperhgnf8 | C19: B53PX3 | D19: dBckyNCFQYIiBH1 | E19: 1 | F19: ajeffry8p@dyndns.org | G19: 45357 | H19: Italy | I19: 45357 | J19: =_xlfn.XLOOKUP(B19,ORDERS[OrderID],ORDERS[Rating],"Null") -> 5 | K19: =IF(FACT_ORDERS[[#This Row],[DeliveryDate]]-FACT_ORDERS[[#This Row],[OrderDate]]<=1,1,0) -> 1 | L19: 15 | M19: =(FACT_ORDERS[[#This Row],[Quantity]]/SUMIF(B$1:B$1643,FACT_ORDERS[[#This Row],[OrderID]],E$1:E$1643))*IF(SUMIFS(FACT_ORDERS[Quantity], FACT_ORDERS[OrderID], FACT_ORDERS[[#This Row],[OrderID]]) < 5, 15, IF(SUMIFS(FACT_ORDERS[Quantity], FACT_ORDERS[OrderID], FACT_ORDERS[[#This Row],[OrderID]]) <= 10, 12, 10)) -> 15 | N19: =(_xlfn.XLOOKUP(D19,DIM_PRODUCTS[ProductID],DIM_PRODUCTS[HandlingFee]))*FACT_ORDERS[[#This Row],[Quantity]] + FACT_ORDERS[[#This Row],[DeliveryFee]] -> 24.05 | O19: =FACT_ORDERS[[#This Row],[TotalPricePerProduct]]-FACT_ORDERS[[#This Row],[DeliveryCost]]-FACT_ORDERS[[#This Row],[OperationsCost]] -> -8.95 | P19: 18
A20: 19 | B20: 5jwn2vfnxm | C20: B53PX3 | D20: dBckyNCFQYIiBH1 | E20: 12 | F20: lpadulabh@bloomberg.com | G20: 45127 | H20: Italy | I20: 45127 | J20: =_xlfn.XLOOKUP(B20,ORDERS[OrderID],ORDERS[Rating],"Null") -> 5 | K20: =IF(FACT_ORDERS[[#This Row],[DeliveryDate]]-FACT_ORDERS[[#This Row],[OrderDate]]<=1,1,0) -> 1 | L20: 15 | M20: =(FACT_ORDERS[[#This Row],[Quantity]]/SUMIF(B$1:B$1643,FACT_ORDERS[[#This Row],[OrderID]],E$1:E$1643))*IF(SUMIFS(FACT_ORDERS[Quantity], FACT_ORDERS[OrderID], FACT_ORDERS[[#This Row],[OrderID]]) < 5, 15, IF(SUMIFS(FACT_ORDERS[Quantity], FACT_ORDERS[OrderID], FACT_ORDERS[[#This Row],[OrderID]]) <= 10, 12, 10)) -> 10 | N20: =(_xlfn.XLOOKUP(D20,DIM_PRODUCTS[ProductID],DIM_PRODUCTS[HandlingFee]))*FACT_ORDERS[[#This Row],[Quantity]] + FACT_ORDERS[[#This Row],[DeliveryFee]] -> 123.6 | O20: =FACT_ORDERS[[#This Row],[TotalPricePerProduct]]-FACT_ORDERS[[#This Row],[DeliveryCost]]-FACT_ORDERS[[#This Row],[OperationsCost]] -> 95.6 | P20: 18
A21: 20 | B21: sa2g5ax52d | C21: B62QI8 | D21: ZWOVrDgk7B2JaDC | E21: 1 | F21: awoodington97@blog.com | G21: 45246 | H21: Italy | I21: 45246 | J21: =_xlfn.XLOOKUP(B21,ORDERS[OrderID],ORDERS[Rating],"Null") -> 1 | K21: =IF(FACT_ORDERS[[#This Row],[DeliveryDate]]-FACT_ORDERS[[#This Row],[OrderDate]]<=1,1,0) -> 1 | L21: 15 | M21: =(FACT_ORDERS[[#This Row],[Quantity]]/SUMIF(B$1:B$1643,FACT_ORDERS[[#This Row],[OrderID]],E$1:E$1643))*IF(SUMIFS(FACT_ORDERS[Quantity], FACT_ORDERS[OrderID], FACT_ORDERS[[#This Row],[OrderID]]) < 5, 15, IF(SUMIFS(FACT_ORDERS[Quantity], FACT_ORDERS[OrderID], FACT_ORDERS[[#This Row],[OrderID]]) <= 10, 12, 10)) -> 15 | N21: =(_xlfn.XLOOKUP(D21,DIM_PRODUCTS[ProductID],DIM_PRODUCTS[HandlingFee]))*FACT_ORDERS[[#This Row],[Quantity]] + FACT_ORDERS[[#This Row],[DeliveryFee]] -> 29.7185 | O21: =FACT_ORDERS[[#This Row],[TotalPricePerProduct]]-FACT_ORDERS[[#This Row],[DeliveryCost]]-FACT_ORDERS[[#This Row],[OperationsCost]] -> -4.2815 | P21: 19
A22: 21 | B22: 6OK205 | C22: B68WJ5 | D22: tV5yMnLtEUjlVZt | E22: 5 | F22: dgwillim3m@pcworld.com | G22: 45269 | H22: Israel | I22: 45269 | J22: =_xlfn.XLOOKUP(B22,ORDERS[OrderID],ORDERS[Rating],"Null") -> 4 | K22: =IF(FACT_ORDERS[[#This Row],[DeliveryDate]]-FACT_ORDERS[[#This Row],[OrderDate]]<=1,1,0) -> 1 | L22: 15 | M22: =(FACT_ORDERS[[#This Row],[Quantity]]/SUMIF(B$1:B$1643,FACT_ORDERS[[#This Row],[OrderID]],E$1:E$1643))*IF(SUMIFS(FACT_ORDERS[Quantity], FACT_ORDERS[OrderID], FACT_ORDERS[[#This Row],[OrderID]]) < 5, 15, IF(SUMIFS(FACT_ORDERS[Quantity], FACT_ORDERS[OrderID], FACT_ORDERS[[#This Row],[OrderID]]) <= 10, 12, 10)) -> 12 | N22: =(_xlfn.XLOOKUP(D22,DIM_PRODUCTS[ProductID],DIM_PRODUCTS[HandlingFee]))*FACT_ORDERS[[#This Row],[Quantity]] + FACT_ORDERS[[#This Row],[DeliveryFee]] -> 87.75 | O22: =FACT_ORDERS[[#This Row],[TotalPricePerProduct]]-FACT_ORDERS[[#This Row],[DeliveryCost]]-FACT_ORDERS[[#This Row],[OperationsCost]] -> 64.75 | P22: 11
A23: 22 | B23: 7lv8jeifvo | C23: B93DN0 | D23: 3xNplN8Q25YQYO8 | E23: 4 | F23: opues3p@ifeng.com | G23: 45382 | H23: Japan | I23: 45382 | J23: =_xlfn.XLOOKUP(B23,ORDERS[OrderID],ORDERS[Rating],"Null") -> 4 | K23: =IF(FACT_ORDERS[[#This Row],[DeliveryDate]]-FACT_ORDERS[[#This Row],[OrderDate]]<=1,1,0) -> 1 | L23: 15 | M23: =(FACT_ORDERS[[#This Row],[Quantity]]/SUMIF(B$1:B$1643,FACT_ORDERS[[#This Row],[OrderID]],E$1:E$1643))*IF(SUMIFS(FACT_ORDERS[Quantity], FACT_ORDERS[OrderID], FACT_ORDERS[[#This Row],[OrderID]]) < 5, 15, IF(SUMIFS(FACT_ORDERS[Quantity], FACT_ORDERS[OrderID], FACT_ORDERS[[#This Row],[OrderID]]) <= 10, 12, 10)) -> 15 | N23: =(_xlfn.XLOOKUP(D23,DIM_PRODUCTS[ProductID],DIM_PRODUCTS[HandlingFee]))*FACT_ORDERS[[#This Row],[Quantity]] + FACT_ORDERS[[#This Row],[DeliveryFee]] -> 37.8 | O23: =FACT_ORDERS[[#This Row],[TotalPricePerProduct]]-FACT_ORDERS[[#This Row],[DeliveryCost]]-FACT_ORDERS[[#This Row],[OperationsCost]] -> 3.8 | P23: 19
A24: 23 | B24: evzpzrwta2 | C24: B93DN0 | D24: 3xNplN8Q25YQYO8 | E24: 4 | F24: rpuleque38@gov.uk | G24: 45257 | H24: Japan | I24: 45258 | J24: =_xlfn.XLOOKUP(B24,ORDERS[OrderID],ORDERS[Rating],"Null") -> 3 | K24: =IF(FACT_ORDERS[[#This Row],[DeliveryDate]]-FACT_ORDERS[[#This Row],[OrderDate]]<=1,1,0) -> 1 | L24: 15 | M24: =(FACT_ORDERS[[#This Row],[Quantity]]/SUMIF(B$1:B$1643,FACT_ORDERS[[#This Row],[OrderID]],E$1:E$1643))*IF(SUMIFS(FACT_ORDERS[Quantity], FACT_ORDERS[OrderID], FACT_ORDERS[[#This Row],[OrderID]]) < 5, 15, IF(SUMIFS(FACT_ORDERS[Quantity], FACT_ORDERS[OrderID], FACT_ORDERS[[#This Row],[OrderID]]) <= 10, 12, 10)) -> 15 | N24: =(_xlfn.XLOOKUP(D24,DIM_PRODUCTS[ProductID],DIM_PRODUCTS[HandlingFee]))*FACT_ORDERS[[#This Row],[Quantity]] + FACT_ORDERS[[#This Row],[DeliveryFee]] -> 37.8 | O24: =FACT_ORDERS[[#This Row],[TotalPricePerProduct]]-FACT_ORDERS[[#This Row],[DeliveryCost]]-FACT_ORDERS[[#This Row],[OperationsCost]] -> 14.8 | P24: 8
A25: 24 | B25: yodkaaiq07 | C25: B93DN0 | D25: 3xNplN8Q25YQYO8 | E25: 6 | F25: rsandels2m@gizmodo.com | G25: 45348 | H25: Japan | I25: 45348 | J25: =_xlfn.XLOOKUP(B25,ORDERS[OrderID],ORDERS[Rating],"Null") -> 1 | K25: =IF(FACT_ORDERS[[#This Row],[DeliveryDate]]-FACT_ORDERS[[#This Row],[OrderDate]]<=1,1,0) -> 1 | L25: 15 | M25: =(FACT_ORDERS[[#This Row],[Quantity]]/SUMIF(B$1:B$1643,FACT_ORDERS[[#This Row],[OrderID]],E$1:E$1643))*IF(SUMIFS(FACT_ORDERS[Quantity], FACT_ORDERS[OrderID], FACT_ORDERS[[#This Row],[OrderID]]) < 5, 15, IF(SUMIFS(FACT_ORDERS[Quantity], FACT_ORDERS[OrderID], FACT_ORDERS[[#This Row],[OrderID]]) <= 10, 12, 10)) -> 12 | N25: =(_xlfn.XLOOKUP(D25,DIM_PRODUCTS[ProductID],DIM_PRODUCTS[HandlingFee]))*FACT_ORDERS[[#This Row],[Quantity]] + FACT_ORDERS[[#This Row],[DeliveryFee]] -> 49.2 | O25: =FACT_ORDERS[[#This Row],[TotalPricePerProduct]]-FACT_ORDERS[[#This Row],[DeliveryCost]]-FACT_ORDERS[[#This Row],[OperationsCost]] -> 23.2 | P25: 14
A26: 25 | B26: cs0hza0vc5 | C26: B93DN0 | D26: 3xNplN8Q25YQYO8 | E26: 10 | F26: epitcock3s@livejournal.com | G26: 45221 | H26: Japan | I26: 45221 | J26: =_xlfn.XLOOKUP(B26,ORDERS[OrderID],ORDERS[Rating],"Null") -> 4 | K26: =IF(FACT_ORDERS[[#This Row],[DeliveryDate]]-FACT_ORDERS[[#This Row],[OrderDate]]<=1,1,0) -> 1 | L26: 15 | M26: =(FACT_ORDERS[[#This Row],[Quantity]]/SUMIF(B$1:B$1643,FACT_ORDERS[[#This Row],[OrderID]],E$1:E$1643))*IF(SUMIFS(FACT_ORDERS[Quantity], FACT_ORDERS[OrderID], FACT_ORDERS[[#This Row],[OrderID]]) < 5, 15, IF(SUMIFS(FACT_ORDERS[Quantity], FACT_ORDERS[OrderID], FACT_ORDERS[[#This Row],[OrderID]]) <= 10, 12, 10)) -> 12 | N26: =(_xlfn.XLOOKUP(D26,DIM_PRODUCTS[ProductID],DIM_PRODUCTS[HandlingFee]))*FACT_ORDERS[[#This Row],[Quantity]] + FACT_ORDERS[[#This Row],[DeliveryFee]] -> 72 | O26: =FACT_ORDERS[[#This Row],[TotalPricePerProduct]]-FACT_ORDERS[[#This Row],[DeliveryCost]]-FACT_ORDERS[[#This Row],[OperationsCost]] -> 44 | P26: 16
A27: 26 | B27: 96943eqnsk | C27: C53IQ0 | D27: TxB1MW6g92BOsv5 | E27: 5 | F27: kbertramd@joomla.org | G27: 45288 | H27: Egypt | I27: 45291 | J27: =_xlfn.XLOOKUP(B27,ORDERS[OrderID],ORDERS[Rating],"Null") -> 5 | K27: =IF(FACT_ORDERS[[#This Row],[DeliveryDate]]-FACT_ORDERS[[#This Row],[OrderDate]]<=1,1,0) -> 0 | L27: 15 | M27: =(FACT_ORDERS[[#This Row],[Quantity]]/SUMIF(B$1:B$1643,FACT_ORDERS[[#This Row],[OrderID]],E$1:E$1643))*IF(SUMIFS(FACT_ORDERS[Quantity], FACT_ORDERS[OrderID], FACT_ORDERS[[#This Row],[OrderID]]) < 5, 15, IF(SUMIFS(FACT_ORDERS[Quantity], FACT_ORDERS[OrderID], FACT_ORDERS[[#This Row],[OrderID]]) <= 10, 12, 10)) -> 12 | N27: =(_xlfn.XLOOKUP(D27,DIM_PRODUCTS[ProductID],DIM_PRODUCTS[HandlingFee]))*FACT_ORDERS[[#This Row],[Quantity]] + FACT_ORDERS[[#This Row],[DeliveryFee]] -> 45.1025 | O27: =FACT_ORDERS[[#This Row],[TotalPricePerProduct]]-FACT_ORDERS[[#This Row],[DeliveryCost]]-FACT_ORDERS[[#This Row],[OperationsCost]] -> 14.1025 | P27: 19
A28: 27 | B28: d9t5asbphe | C28: C57DA7 | D28: 8DEuIulZ5q65lfG | E28: 6 | F28: dbenitti2f@wikipedia.org | G28: 45405 | H28: Italy | I28: 45405 | J28: =_xlfn.XLOOKUP(B28,ORDERS[OrderID],ORDERS[Rating],"Null") -> 4 | K28: =IF(FACT_ORDERS[[#This Row],[DeliveryDate]]-FACT_ORDERS[[#This Row],[OrderDate]]<=1,1,0) -> 1 | L28: 15 | M28: =(FACT_ORDERS[[#This Row],[Quantity]]/SUMIF(B$1:B$1643,FACT_ORDERS[[#This Row],[OrderID]],E$1:E$1643))*IF(SUMIFS(FACT_ORDERS[Quantity], FACT_ORDERS[OrderID], FACT_ORDERS[[#This Row],[OrderID]]) < 5, 15, IF(SUMIFS(FACT_ORDERS[Quantity], FACT_ORDERS[OrderID], FACT_ORDERS[[#This Row],[OrderID]]) <= 10, 12, 10)) -> 12 | N28: =(_xlfn.XLOOKUP(D28,DIM_PRODUCTS[ProductID],DIM_PRODUCTS[HandlingFee]))*FACT_ORDERS[[#This Row],[Quantity]] + FACT_ORDERS[[#This Row],[DeliveryFee]] -> 28.8 | O28: =FACT_ORDERS[[#This Row],[TotalPricePerProduct]]-FACT_ORDERS[[#This Row],[DeliveryCost]]-FACT_ORDERS[[#This Row],[OperationsCost]] -> -0.2 | P28: 17
... A30: 29 | B30: V4tNre | C30: C68SH6 | D30: XFOzjjAVD7eNwZG | E30: 11 | F30: orugglesa9@freewebs.com | G30: 45393 | H30: Belize | I30: 45396 | J30: =_xlfn.XLOOKUP(B30,ORDERS[OrderID],ORDERS[Rating],"Null") -> 4 | K30: =IF(FACT_ORDERS[[#This Row],[DeliveryDate]]-FACT_ORDERS[[#This Row],[OrderDate]]<=1,1,0) -> 0 | L30: 15 | M30: =(FACT_ORDERS[[#This Row],[Quantity]]/SUMIF(B$1:B$1643,FACT_ORDERS[[#This Row],[OrderID]],E$1:E$1643))*IF(SUMIFS(FACT_ORDERS[Quantity], FACT_ORDERS[OrderID], FACT_ORDERS[[#This Row],[OrderID]]) < 5, 15, IF(SUMIFS(FACT_ORDERS[Quantity], FACT_ORDERS[OrderID], FACT_ORDERS[[#This Row],[OrderID]]) <= 10, 12, 10)) -> 10 | N30: =(_xlfn.XLOOKUP(D30,DIM_PRODUCTS[ProductID],DIM_PRODUCTS[HandlingFee]))*FACT_ORDERS[[#This Row],[Quantity]] + FACT_ORDERS[[#This Row],[DeliveryFee]] -> 93.65 | O30: =FACT_ORDERS[[#This Row],[TotalPricePerProduct]]-FACT_ORDERS[[#This Row],[DeliveryCost]]-FACT_ORDERS[[#This Row],[OperationsCost]] -> 65.65 | P30: 18
A31: 30 | B31: 91665 | C31: C69AP2 | D31: SUtRjm5YT410p8T | E31: 2 | F31: fsallisl@mac.com | G31: 45288 | H31: Italy | I31: 45288 | J31: =_xlfn.XLOOKUP(B31,ORDERS[OrderID],ORDERS[Rating],"Null") -> 5 | K31: =IF(FACT_ORDERS[[#This Row],[DeliveryDate]]-FACT_ORDERS[[#This Row],[OrderDate]]<=1,1,0) -> 1 | L31: 15 | M31: =(FACT_ORDERS[[#This Row],[Quantity]]/SUMIF(B$1:B$1643,FACT_ORDERS[[#This Row],[OrderID]],E$1:E$1643))*IF(SUMIFS(FACT_ORDERS[Quantity], FACT_ORDERS[OrderID], FACT_ORDERS[[#This Row],[OrderID]]) < 5, 15, IF(SUMIFS(FACT_ORDERS[Quantity], FACT_ORDERS[OrderID], FACT_ORDERS[[#This Row],[OrderID]]) <= 10, 12, 10)) -> 15 | N31: =(_xlfn.XLOOKUP(D31,DIM_PRODUCTS[ProductID],DIM_PRODUCTS[HandlingFee]))*FACT_ORDERS[[#This Row],[Quantity]] + FACT_ORDERS[[#This Row],[DeliveryFee]] -> 41.126 | O31: =FACT_ORDERS[[#This Row],[TotalPricePerProduct]]-FACT_ORDERS[[#This Row],[DeliveryCost]]-FACT_ORDERS[[#This Row],[OperationsCost]] -> 12.126 | P31: 14
A32: 31 | B32: amh1jl7wnu | C32: C77AE8 | D32: PiWigEgirUclMuO | E32: 11 | F32: asager7v@prweb.com | G32: 45379 | H32: Japan | I32: 45379 | J32: =_xlfn.XLOOKUP(B32,ORDERS[OrderID],ORDERS[Rating],"Null") -> 5 | K32: =IF(FACT_ORDERS[[#This Row],[DeliveryDate]]-FACT_ORDERS[[#This Row],[OrderDate]]<=1,1,0) -> 1 | L32: 15 | M32: =(FACT_ORDERS[[#This Row],[Quantity]]/SUMIF(B$1:B$1643,FACT_ORDERS[[#This Row],[OrderID]],E$1:E$1643))*IF(SUMIFS(FACT_ORDERS[Quantity], FACT_ORDERS[OrderID], FACT_ORDERS[[#This Row],[OrderID]]) < 5, 15, IF(SUMIFS(FACT_ORDERS[Quantity], FACT_ORDERS[OrderID], FACT_ORDERS[[#This Row],[OrderID]]) <= 10, 12, 10)) -> 10 | N32: =(_xlfn.XLOOKUP(D32,DIM_PRODUCTS[ProductID],DIM_PRODUCTS[HandlingFee]))*FACT_ORDERS[[#This Row],[Quantity]] + FACT_ORDERS[[#This Row],[DeliveryFee]] -> 167.35 | O32: =FACT_ORDERS[[#This Row],[TotalPricePerProduct]]-FACT_ORDERS[[#This Row],[DeliveryCost]]-FACT_ORDERS[[#This Row],[OperationsCost]] -> 139.35 | P32: 18
A33: 32 | B33: I0qlqR | C33: C84NX0 | D33: kMvmAelhSE8KqAu | E33: 9 | F33: lclerc4e@illinois.edu | G33: 45304 | H33: Japan | I33: 45305 | J33: =_xlfn.XLOOKUP(B33,ORDERS[OrderID],ORDERS[Rating],"Null") -> 4 | K33: =IF(FACT_ORDERS[[#This Row],[DeliveryDate]]-FACT_ORDERS[[#This Row],[OrderDate]]<=1,1,0) -> 1 | L33: 15 | M33: =(FACT_ORDERS[[#This Row],[Quantity]]/SUMIF(B$1:B$1643,FACT_ORDERS[[#This Row],[OrderID]],E$1:E$1643))*IF(SUMIFS(FACT_ORDERS[Quantity], FACT_ORDERS[OrderID], FACT_ORDERS[[#This Row],[OrderID]]) < 5, 15, IF(SUMIFS(FACT_ORDERS[Quantity], FACT_ORDERS[OrderID], FACT_ORDERS[[#This Row],[OrderID]]) <= 10, 12, 10)) -> 12 | N33: =(_xlfn.XLOOKUP(D33,DIM_PRODUCTS[ProductID],DIM_PRODUCTS[HandlingFee]))*FACT_ORDERS[[#This Row],[Quantity]] + FACT_ORDERS[[#This Row],[DeliveryFee]] -> 43.35 | O33: =FACT_ORDERS[[#This Row],[TotalPricePerProduct]]-FACT_ORDERS[[#This Row],[DeliveryCost]]-FACT_ORDERS[[#This Row],[OperationsCost]] -> 17.35 | P33: 14
A34: 33 | B34: yYL7bk | C34: C84NX0 | D34: kMvmAelhSE8KqAu | E34: 6 | F34: pjearyap@statcounter.com | G34: 45273 | H34: Japan | I34: 45276 | J34: =_xlfn.XLOOKUP(B34,ORDERS[OrderID],ORDERS[Rating],"Null") -> 1 | K34: =IF(FACT_ORDERS[[#This Row],[DeliveryDate]]-FACT_ORDERS[[#This Row],[OrderDate]]<=1,1,0) -> 0 | L34: 15 | M34: =(FACT_ORDERS[[#This Row],[Quantity]]/SUMIF(B$1:B$1643,FACT_ORDERS[[#This Row],[OrderID]],E$1:E$1643))*IF(SUMIFS(FACT_ORDERS[Quantity], FACT_ORDERS[OrderID], FACT_ORDERS[[#This Row],[OrderID]]) < 5, 15, IF(SUMIFS(FACT_ORDERS[Quantity], FACT_ORDERS[OrderID], FACT_ORDERS[[#This Row],[OrderID]]) <= 10, 12, 10)) -> 12 | N34: =(_xlfn.XLOOKUP(D34,DIM_PRODUCTS[ProductID],DIM_PRODUCTS[HandlingFee]))*FACT_ORDERS[[#This Row],[Quantity]] + FACT_ORDERS[[#This Row],[DeliveryFee]] -> 33.9 | O34: =FACT_ORDERS[[#This Row],[TotalPricePerProduct]]-FACT_ORDERS[[#This Row],[DeliveryCost]]-FACT_ORDERS[[#This Row],[OperationsCost]] -> 10.9 | P34: 11
A35: 34 | B35: XbEKGy | C35: C84NX0 | D35: kMvmAelhSE8KqAu | E35: 9 | F35: sorhtmannb7@instagram.com | G35: 45148 | H35: Japan | I35: 45149 | J35: =_xlfn.XLOOKUP(B35,ORDERS[OrderID],ORDERS[Rating],"Null") -> 1 | K35: =IF(FACT_ORDERS[[#This Row],[DeliveryDate]]-FACT_ORDERS[[#This Row],[OrderDate]]<=1,1,0) -> 1 | L35: 15 | M35: =(FACT_ORDERS[[#This Row],[Quantity]]/SUMIF(B$1:B$1643,FACT_ORDERS[[#This Row],[OrderID]],E$1:E$1643))*IF(SUMIFS(FACT_ORDERS[Quantity], FACT_ORDERS[OrderID], FACT_ORDERS[[#This Row],[OrderID]]) < 5, 15, IF(SUMIFS(FACT_ORDERS[Quantity], FACT_ORDERS[OrderID], FACT_ORDERS[[#This Row],[OrderID]]) <= 10, 12, 10)) -> 12 | N35: =(_xlfn.XLOOKUP(D35,DIM_PRODUCTS[ProductID],DIM_PRODUCTS[HandlingFee]))*FACT_ORDERS[[#This Row],[Quantity]] + FACT_ORDERS[[#This Row],[DeliveryFee]] -> 43.35 | O35: =FACT_ORDERS[[#This Row],[TotalPricePerProduct]]-FACT_ORDERS[[#This Row],[DeliveryCost]]-FACT_ORDERS[[#This Row],[OperationsCost]] -> 21.35 | P35: 10
A36: 35 | B36: x3pdx992aj | C36: C86GN0 | D36: j0jhVZbxhGIdOHY | E36: 6 | F36: mbunten91@elegantthemes.com | G36: 45413 | H36: Italy | I36: 45413 | J36: =_xlfn.XLOOKUP(B36,ORDERS[OrderID],ORDERS[Rating],"Null") -> 3 | K36: =IF(FACT_ORDERS[[#This Row],[DeliveryDate]]-FACT_ORDERS[[#This Row],[OrderDate]]<=1,1,0) -> 1 | L36: 15 | M36: =(FACT_ORDERS[[#This Row],[Quantity]]/SUMIF(B$1:B$1643,FACT_ORDERS[[#This Row],[OrderID]],E$1:E$1643))*IF(SUMIFS(FACT_ORDERS[Quantity], FACT_ORDERS[OrderID], FACT_ORDERS[[#This Row],[OrderID]]) < 5, 15, IF(SUMIFS(FACT_ORDERS[Quantity], FACT_ORDERS[OrderID], FACT_ORDERS[[#This Row],[OrderID]]) <= 10, 12, 10)) -> 12 | N36: =(_xlfn.XLOOKUP(D36,DIM_PRODUCTS[ProductID],DIM_PRODUCTS[HandlingFee]))*FACT_ORDERS[[#This Row],[Quantity]] + FACT_ORDERS[[#This Row],[DeliveryFee]] -> 44.865 | O36: =FACT_ORDERS[[#This Row],[TotalPricePerProduct]]-FACT_ORDERS[[#This Row],[DeliveryCost]]-FACT_ORDERS[[#This Row],[OperationsCost]] -> 24.865 | P36: 8
A37: 36 | B37: ZYeR3v | C37: C91HN9 | D37: YB0QCbtRV2JPgrS | E37: 8 | F37: tmcsheea5@ted.com | G37: 45273 | H37: Canada | I37: 45274 | J37: =_xlfn.XLOOKUP(B37,ORDERS[OrderID],ORDERS[Rating],"Null") -> 2 | K37: =IF(FACT_ORDERS[[#This Row],[DeliveryDate]]-FACT_ORDERS[[#This Row],[OrderDate]]<=1,1,0) -> 1 | L37: 15 | M37: =(FACT_ORDERS[[#This Row],[Quantity]]/SUMIF(B$1:B$1643,FACT_ORDERS[[#This Row],[OrderID]],E$1:E$1643))*IF(SUMIFS(FACT_ORDERS[Quantity], FACT_ORDERS[OrderID], FACT_ORDERS[[#This Row],[OrderID]]) < 5, 15, IF(SUMIFS(FACT_ORDERS[Quantity], FACT_ORDERS[OrderID], FACT_ORDERS[[#This Row],[OrderID]]) <= 10, 12, 10)) -> 12 | N37: =(_xlfn.XLOOKUP(D37,DIM_PRODUCTS[ProductID],DIM_PRODUCTS[HandlingFee]))*FACT_ORDERS[[#This Row],[Quantity]] + FACT_ORDERS[[#This Row],[DeliveryFee]] -> 102.6 | O37: =FACT_ORDERS[[#This Row],[TotalPricePerProduct]]-FACT_ORDERS[[#This Row],[DeliveryCost]]-FACT_ORDERS[[#This Row],[OperationsCost]] -> 84.6 | P37: 6
A38: 37 | B38: vDXSwx | C38: C91HN9 | D38: YB0QCbtRV2JPgrS | E38: 7 | F38: oklassmann4s@toplist.cz | G38: 45379 | H38: Canada | I38: 45380 | J38: =_xlfn.XLOOKUP(B38,ORDERS[OrderID],ORDERS[Rating],"Null") -> 3 | K38: =IF(FACT_ORDERS[[#This Row],[DeliveryDate]]-FACT_ORDERS[[#This Row],[OrderDate]]<=1,1,0) -> 1 | L38: 15 | M38: =(FACT_ORDERS[[#This Row],[Quantity]]/SUMIF(B$1:B$1643,FACT_ORDERS[[#This Row],[OrderID]],E$1:E$1643))*IF(SUMIFS(FACT_ORDERS[Quantity], FACT_ORDERS[OrderID], FACT_ORDERS[[#This Row],[OrderID]]) < 5, 15, IF(SUMIFS(FACT_ORDERS[Quantity], FACT_ORDERS[OrderID], FACT_ORDERS[[#This Row],[OrderID]]) <= 10, 12, 10)) -> 12 | N38: =(_xlfn.XLOOKUP(D38,DIM_PRODUCTS[ProductID],DIM_PRODUCTS[HandlingFee]))*FACT_ORDERS[[#This Row],[Quantity]] + FACT_ORDERS[[#This Row],[DeliveryFee]] -> 91.65 | O38: =FACT_ORDERS[[#This Row],[TotalPricePerProduct]]-FACT_ORDERS[[#This Row],[DeliveryCost]]-FACT_ORDERS[[#This Row],[OperationsCost]] -> 70.65 | P38: 9
A39: 38 | B39: h0kPxn | C39: C91HN9 | D39: YB0QCbtRV2JPgrS | E39: 2 | F39: aklempkebj@quantcast.com | G39: 45423 | H39: Canada | I39: 45423 | J39: =_xlfn.XLOOKUP(B39,ORDERS[OrderID],ORDERS[Rating],"Null") -> 1 | K39: =IF(FACT_ORDERS[[#This Row],[DeliveryDate]]-FACT_ORDERS[[#This Row],[OrderDate]]<=1,1,0) -> 1 | L39: 3 | M39: =(FACT_ORDERS[[#This Row],[Quantity]]/SUMIF(B$1:B$1643,FACT_ORDERS[[#This Row],[OrderID]],E$1:E$1643))*IF(SUMIFS(FACT_ORDERS[Quantity], FACT_ORDERS[OrderID], FACT_ORDERS[[#This Row],[OrderID]]) < 5, 15, IF(SUMIFS(FACT_ORDERS[Quantity], FACT_ORDERS[OrderID], FACT_ORDERS[[#This Row],[OrderID]]) <= 10, 12, 10)) -> 2.4 | N39: =(_xlfn.XLOOKUP(D39,DIM_PRODUCTS[ProductID],DIM_PRODUCTS[HandlingFee]))*FACT_ORDERS[[#This Row],[Quantity]] + FACT_ORDERS[[#This Row],[DeliveryFee]] -> 24.9 | O39: =FACT_ORDERS[[#This Row],[TotalPricePerProduct]]-FACT_ORDERS[[#This Row],[DeliveryCost]]-FACT_ORDERS[[#This Row],[OperationsCost]] -> 3.5 | P39: 19
A40: 39 | B40: QfCJZk | C40: C91HN9 | D40: YB0QCbtRV2JPgrS | E40: 11 | F40: aseallyw@rediff.com | G40: 45200 | H40: Canada | I40: 45200 | J40: =_xlfn.XLOOKUP(B40,ORDERS[OrderID],ORDERS[Rating],"Null") -> 3 | K40: =IF(FACT_ORDERS[[#This Row],[DeliveryDate]]-FACT_ORDERS[[#This Row],[OrderDate]]<=1,1,0) -> 1 | L40: 11 | M40: =(FACT_ORDERS[[#This Row],[Quantity]]/SUMIF(B$1:B$1643,FACT_ORDERS[[#This Row],[OrderID]],E$1:E$1643))*IF(SUMIFS(FACT_ORDERS[Quantity], FACT_ORDERS[OrderID], FACT_ORDERS[[#This Row],[OrderID]]) < 5, 15, IF(SUMIFS(FACT_ORDERS[Quantity], FACT_ORDERS[OrderID], FACT_ORDERS[[#This Row],[OrderID]]) <= 10, 12, 10)) -> 7.3333333 | N40: =(_xlfn.XLOOKUP(D40,DIM_PRODUCTS[ProductID],DIM_PRODUCTS[HandlingFee]))*FACT_ORDERS[[#This Row],[Quantity]] + FACT_ORDERS[[#This Row],[DeliveryFee]] -> 131.45 | O40: =FACT_ORDERS[[#This Row],[TotalPricePerProduct]]-FACT_ORDERS[[#This Row],[DeliveryCost]]-FACT_ORDERS[[#This Row],[OperationsCost]] -> 107.11667 | P40: 17
A41: 40 | B41: k2kYAu | C41: C91HN9 | D41: YB0QCbtRV2JPgrS | E41: 7 | F41: rkippie4d@msu.edu | G41: 45473 | H41: Canada | I41: 45474 | J41: =_xlfn.XLOOKUP(B41,ORDERS[OrderID],ORDERS[Rating],"Null") -> 1 | K41: =IF(FACT_ORDERS[[#This Row],[DeliveryDate]]-FACT_ORDERS[[#This Row],[OrderDate]]<=1,1,0) -> 1 | L41: 7.5 | M41: =(FACT_ORDERS[[#This Row],[Quantity]]/SUMIF(B$1:B$1643,FACT_ORDERS[[#This Row],[OrderID]],E$1:E$1643))*IF(SUMIFS(FACT_ORDERS[Quantity], FACT_ORDERS[OrderID], FACT_ORDERS[[#This Row],[OrderID]]) < 5, 15, IF(SUMIFS(FACT_ORDERS[Quantity], FACT_ORDERS[OrderID], FACT_ORDERS[[#This Row],[OrderID]]) <= 10, 12, 10)) -> 5 | N41: =(_xlfn.XLOOKUP(D41,DIM_PRODUCTS[ProductID],DIM_PRODUCTS[HandlingFee]))*FACT_ORDERS[[#This Row],[Quantity]] + FACT_ORDERS[[#This Row],[DeliveryFee]] -> 84.15 | O41: =FACT_ORDERS[[#This Row],[TotalPricePerProduct]]-FACT_ORDERS[[#This Row],[DeliveryCost]]-FACT_ORDERS[[#This Row],[OperationsCost]] -> 63.15 | P41: 16
A42: 41 | B42: IWTwWR | C42: C91HN9 | D42: YB0QCbtRV2JPgrS | E42: 7 | F42: hbumphrieso@omniture.com | G42: 45340 | H42: Canada | I42: 45340 | J42: =_xlfn.XLOOKUP(B42,ORDERS[OrderID],ORDERS[Rating],"Null") -> 3 | K42: =IF(FACT_ORDERS[[#This Row],[DeliveryDate]]-FACT_ORDERS[[#This Row],[OrderDate]]<=1,1,0) -> 1 | L42: 15 | M42: =(FACT_ORDERS[[#This Row],[Quantity]]/SUMIF(B$1:B$1643,FACT_ORDERS[[#This Row],[OrderID]],E$1:E$1643))*IF(SUMIFS(FACT_ORDERS[Quantity], FACT_ORDERS[OrderID], FACT_ORDERS[[#This Row],[OrderID]]) < 5, 15, IF(SUMIFS(FACT_ORDERS[Quantity], FACT_ORDERS[OrderID], FACT_ORDERS[[#This Row],[OrderID]]) <= 10, 12, 10)) -> 12 | N42: =(_xlfn.XLOOKUP(D42,DIM_PRODUCTS[ProductID],DIM_PRODUCTS[HandlingFee]))*FACT_ORDERS[[#This Row],[Quantity]] + FACT_ORDERS[[#This Row],[DeliveryFee]] -> 91.65 | O42: =FACT_ORDERS[[#This Row],[TotalPricePerProduct]]-FACT_ORDERS[[#This Row],[DeliveryCost]]-FACT_ORDERS[[#This Row],[OperationsCost]] -> 65.65 | P42: 14
...

Sheet FACT_SEARCHES
A1: DW_SEARCHES | B1: IPAddress | C1: SearchDate | D1: Email | E1: Text | F1: isConversion
A2: 5043 | B2: 22.207.202.213/26 | C2: 45134 | D2: gmccard12@alibaba.com | E2: Love&romance | F2: =IF(AND(B2=SEARCHES!A2, C2=SEARCHES!B2), IF(SEARCHES!D2<>"NULL", 1, 0), 0) -> 1
A3: 5044 | B3: 222.150.87.12/10 | C3: 45158 | D3: dmchirriedu@meetup.com | E3: Best Seller | F3: =IF(AND(B3=SEARCHES!A3, C3=SEARCHES!B3), IF(SEARCHES!D3<>"NULL", 1, 0), 0) -> 1
A4: 5045 | B4: 38.154.167.154/19 | C4: 45297 | D4: gkopf5v@dailymail.co.uk | E4: Summer | F4: =IF(AND(B4=SEARCHES!A4, C4=SEARCHES!B4), IF(SEARCHES!D4<>"NULL", 1, 0), 0) -> 1
A5: 5046 | B5: 170.14.180.222/18 | C5: 45314 | D5: dimosg@discuz.net | E5: Womans Day | F5: =IF(AND(B5=SEARCHES!A5, C5=SEARCHES!B5), IF(SEARCHES!D5<>"NULL", 1, 0), 0) -> 1
A6: 5047 | B6: 16.58.195.27/16 | C6: 45176 | D6: shoudhury5d@slashdot.org | E6: Anniversary | F6: =IF(AND(B6=SEARCHES!A6, C6=SEARCHES!B6), IF(SEARCHES!D6<>"NULL", 1, 0), 0) -> 1
A7: 5048 | B7: 19.60.9.136/13 | C7: 45169 | D7: bstebbinsfc@chron.com | E7: Thanksgiving | F7: =IF(AND(B7=SEARCHES!A7, C7=SEARCHES!B7), IF(SEARCHES!D7<>"NULL", 1, 0), 0) -> 1
A8: 5049 | B8: 210.44.175.135/11 | C8: 45146 | D8: fjanning1w@1688.com | E8: Best Seller | F8: =IF(AND(B8=SEARCHES!A8, C8=SEARCHES!B8), IF(SEARCHES!D8<>"NULL", 1, 0), 0) -> 1
A9: 5050 | B9: 176.79.13.233/26 | C9: 45232 | D9: gkopf5v@dailymail.co.uk | E9: Best Seller | F9: =IF(AND(B9=SEARCHES!A9, C9=SEARCHES!B9), IF(SEARCHES!D9<>"NULL", 1, 0), 0) -> 1
A10: 5051 | B10: 59.179.107.164/27 | C10: 45429 | D10: jibbesoneu@skype.com | E10: Anniversary | F10: =IF(AND(B10=SEARCHES!A10, C10=SEARCHES!B10), IF(SEARCHES!D10<>"NULL", 1, 0), 0) -> 1
A11: 5052 | B11: 123.255.137.116/12 | C11: 45217 | D11: jhinrichsene0@wp.com | E11: Thank You | F11: =IF(AND(B11=SEARCHES!A11, C11=SEARCHES!B11), IF(SEARCHES!D11<>"NULL", 1, 0), 0) -> 1
